<?xml version="1.0" ?>
<testsuite errors="2" failures="0" name="FlaskApp-20200610160321" tests="2" time="0.001">
	<testcase classname="FlaskApp" name="test_hello" time="0.001">
		<error message="type object 'FlaskApp' has no attribute 'app'" type="AttributeError">
<![CDATA[Traceback (most recent call last):
  File "test.py", line 9, in setUp
    FlaskApp.app.testing = True
AttributeError: type object 'FlaskApp' has no attribute 'app'
]]>		</error>
	</testcase>
	<testcase classname="FlaskApp" name="test_hello_index" time="0.000">
		<error message="type object 'FlaskApp' has no attribute 'app'" type="AttributeError">
<![CDATA[Traceback (most recent call last):
  File "test.py", line 9, in setUp
    FlaskApp.app.testing = True
AttributeError: type object 'FlaskApp' has no attribute 'app'
]]>		</error>
	</testcase>
	<system-out>
<![CDATA[]]>	</system-out>
	<system-err>
<![CDATA[]]>	</system-err>
</testsuite>
